postgres=# GRANT ALL ON SCHEMA public TO luggstock;
GRANT
postgres=# ALTER ROLE luggstock WITH CREATEDB;
ALTER ROLE
postgres=# \q
(venv) root@orion:/datos/www/StockManagerLocal# python main.py
Traceback (most recent call last):
  File "/datos/www/StockManagerLocal/venv/lib/python3.11/site-packages/sqlalchemy/engine/base.py", line 1969, in _exec_single_context
    self.dialect.do_execute(
  File "/datos/www/StockManagerLocal/venv/lib/python3.11/site-packages/sqlalchemy/engine/default.py", line 922, in do_execute
    cursor.execute(statement, parameters)
psycopg2.errors.InsufficientPrivilege: permiso denegado al esquema public
LINE 2: CREATE TABLE "user" (
                     ^


The above exception was the direct cause of the following exception:

Traceback (most recent call last):
  File "/datos/www/StockManagerLocal/main.py", line 1, in <module>
    from app import app
  File "/datos/www/StockManagerLocal/app.py", line 64, in <module>
    db.create_all()
  File "/datos/www/StockManagerLocal/venv/lib/python3.11/site-packages/flask_sqlalchemy/extension.py", line 900, in create_all
    self._call_for_binds(bind_key, "create_all")
  File "/datos/www/StockManagerLocal/venv/lib/python3.11/site-packages/flask_sqlalchemy/extension.py", line 881, in _call_for_binds
    getattr(metadata, op_name)(bind=engine)
  File "/datos/www/StockManagerLocal/venv/lib/python3.11/site-packages/sqlalchemy/sql/schema.py", line 5828, in create_all
    bind._run_ddl_visitor(
  File "/datos/www/StockManagerLocal/venv/lib/python3.11/site-packages/sqlalchemy/engine/base.py", line 3243, in _run_ddl_visitor
    conn._run_ddl_visitor(visitorcallable, element, **kwargs)
  File "/datos/www/StockManagerLocal/venv/lib/python3.11/site-packages/sqlalchemy/engine/base.py", line 2447, in _run_ddl_visitor
    visitorcallable(self.dialect, self, **kwargs).traverse_single(element)
  File "/datos/www/StockManagerLocal/venv/lib/python3.11/site-packages/sqlalchemy/sql/visitors.py", line 671, in traverse_single
    return meth(obj, **kw)
           ^^^^^^^^^^^^^^^
  File "/datos/www/StockManagerLocal/venv/lib/python3.11/site-packages/sqlalchemy/sql/ddl.py", line 919, in visit_metadata
    self.traverse_single(
  File "/datos/www/StockManagerLocal/venv/lib/python3.11/site-packages/sqlalchemy/sql/visitors.py", line 671, in traverse_single
    return meth(obj, **kw)
           ^^^^^^^^^^^^^^^
  File "/datos/www/StockManagerLocal/venv/lib/python3.11/site-packages/sqlalchemy/sql/ddl.py", line 957, in visit_table
    )._invoke_with(self.connection)
      ^^^^^^^^^^^^^^^^^^^^^^^^^^^^^
  File "/datos/www/StockManagerLocal/venv/lib/python3.11/site-packages/sqlalchemy/sql/ddl.py", line 315, in _invoke_with
    return bind.execute(self)
           ^^^^^^^^^^^^^^^^^^
  File "/datos/www/StockManagerLocal/venv/lib/python3.11/site-packages/sqlalchemy/engine/base.py", line 1416, in execute
    return meth(
           ^^^^^
  File "/datos/www/StockManagerLocal/venv/lib/python3.11/site-packages/sqlalchemy/sql/ddl.py", line 181, in _execute_on_connection
    return connection._execute_ddl(
           ^^^^^^^^^^^^^^^^^^^^^^^^
  File "/datos/www/StockManagerLocal/venv/lib/python3.11/site-packages/sqlalchemy/engine/base.py", line 1528, in _execute_ddl
    ret = self._execute_context(
          ^^^^^^^^^^^^^^^^^^^^^^
  File "/datos/www/StockManagerLocal/venv/lib/python3.11/site-packages/sqlalchemy/engine/base.py", line 1848, in _execute_context
    return self._exec_single_context(
           ^^^^^^^^^^^^^^^^^^^^^^^^^^
  File "/datos/www/StockManagerLocal/venv/lib/python3.11/site-packages/sqlalchemy/engine/base.py", line 1988, in _exec_single_context
    self._handle_dbapi_exception(
  File "/datos/www/StockManagerLocal/venv/lib/python3.11/site-packages/sqlalchemy/engine/base.py", line 2343, in _handle_dbapi_exception
    raise sqlalchemy_exception.with_traceback(exc_info[2]) from e
  File "/datos/www/StockManagerLocal/venv/lib/python3.11/site-packages/sqlalchemy/engine/base.py", line 1969, in _exec_single_context
    self.dialect.do_execute(
  File "/datos/www/StockManagerLocal/venv/lib/python3.11/site-packages/sqlalchemy/engine/default.py", line 922, in do_execute
    cursor.execute(statement, parameters)
sqlalchemy.exc.ProgrammingError: (psycopg2.errors.InsufficientPrivilege) permiso denegado al esquema public
LINE 2: CREATE TABLE "user" (
                     ^

[SQL: 
CREATE TABLE "user" (
	id SERIAL NOT NULL, 
	email VARCHAR(120) NOT NULL, 
	password_hash VARCHAR(255), 
	is_active BOOLEAN, 
	created_at TIMESTAMP WITHOUT TIME ZONE, 
	PRIMARY KEY (id), 
	UNIQUE (email)
)

]
